Workbook

Sheet Folha1
A1: Disciplina | B1: Nível / Categoria | C1: Subcategoria | D1: Conteúdo / Tópico | E1: Status | F1: teste | G1: C&
A2: Matemática | B2: Nível 1 - Fundamentos | D2: Sistema de numeração | E2: Finalizado | F2: =LEFT(A2,2) -> Ma | G2: =A2&" - "&D2 -> Matemática - Sistema de numeração
A3: Matemática | B3: Nível 1 - Fundamentos | D3: Operações básicas | E3: Finalizado | F3: =LEFT(A3,2) -> Ma | G3: =A3&" - "&D3 -> Matemática - Operações básicas
A4: Matemática | B4: Nível 1 - Fundamentos | D4: Potenciação | E4: Finalizado | F4: =LEFT(A4,2) -> Ma | G4: =A4&" - "&D4 -> Matemática - Potenciação
A5: Matemática | B5: Nível 1 - Fundamentos | D5: Radiciação | E5: Não Iniciado | F5: =LEFT(A5,2) -> Ma | G5: =A5&" - "&D5 -> Matemática - Radiciação
A6: Matemática | B6: Nível 1 - Fundamentos | D6: MMC e MDC | E6: Não Iniciado | F6: =LEFT(A6,2) -> Ma | G6: =A6&" - "&D6 -> Matemática - MMC e MDC
A7: Matemática | B7: Nível 1 - Fundamentos | D7: Divisibilidade | E7: Não Iniciado | F7: =LEFT(A7,2) -> Ma | G7: =A7&" - "&D7 -> Matemática - Divisibilidade
A8: Matemática | B8: Nível 1 - Fundamentos | D8: Frações | E8: Não Iniciado | F8: =LEFT(A8,2) -> Ma | G8: =A8&" - "&D8 -> Matemática - Frações
A9: Matemática | B9: Nível 1 - Fundamentos | D9: Números decimais | E9: Não Iniciado | F9: =LEFT(A9,2) -> Ma | G9: =A9&" - "&D9 -> Matemática - Números decimais
A10: Matemática | B10: Nível 1 - Fundamentos | D10: Razões e proporções | E10: Não Iniciado | F10: =LEFT(A10,2) -> Ma | G10: =A10&" - "&D10 -> Matemática - Razões e proporções
A11: Matemática | B11: Nível 1 - Fundamentos | D11: Regra de três simples | E11: Não Iniciado | F11: =LEFT(A11,2) -> Ma | G11: =A11&" - "&D11 -> Matemática - Regra de três simples
A12: Matemática | B12: Nível 1 - Fundamentos | D12: Regra de três composta | E12: Não Iniciado | F12: =LEFT(A12,2) -> Ma | G12: =A12&" - "&D12 -> Matemática - Regra de três composta
A13: Matemática | B13: Nível 1 - Fundamentos | D13: Porcentagem | E13: Não Iniciado | F13: =LEFT(A13,2) -> Ma | G13: =A13&" - "&D13 -> Matemática - Porcentagem
... A18: Matemática | B18: Nível 1 - Fundamentos | D18: Conversão de unidades | E18: Não Iniciado | F18: =LEFT(A18,2) -> Ma | G18: =A18&" - "&D18 -> Matemática - Conversão de unidades
A19: Matemática | B19: Nível 2 - Álgebra | C19: Expressões Algébricas | D19: Produtos notáveis | E19: Não Iniciado | F19: =LEFT(A19,2) -> Ma | G19: =A19&" - "&D19 -> Matemática - Produtos notáveis
A20: Matemática | B20: Nível 2 - Álgebra | C20: Expressões Algébricas | D20: Fatoração | E20: Não Iniciado | F20: =LEFT(A20,2) -> Ma | G20: =A20&" - "&D20 -> Matemática - Fatoração
A21: Matemática | B21: Nível 2 - Álgebra | C21: Expressões Algébricas | D21: Frações algébricas | E21: Não Iniciado | F21: =LEFT(A21,2) -> Ma | G21: =A21&" - "&D21 -> Matemática - Frações algébricas
A22: Matemática | B22: Nível 2 - Álgebra | C22: Expressões Algébricas | D22: Equações do 1º grau | E22: Não Iniciado | F22: =LEFT(A22,2) -> Ma | G22: =A22&" - "&D22 -> Matemática - Equações do 1º grau
A23: Matemática | B23: Nível 2 - Álgebra | C23: Expressões Algébricas | D23: Sistemas lineares | E23: Não Iniciado | F23: =LEFT(A23,2) -> Ma | G23: =A23&" - "&D23 -> Matemática - Sistemas lineares
A24: Matemática | B24: Nível 2 - Álgebra | C24: Expressões Algébricas | D24: Inequações | E24: Não Iniciado | F24: =LEFT(A24,2) -> Ma | G24: =A24&" - "&D24 -> Matemática - Inequações
A25: Matemática | B25: Nível 2 - Álgebra | C25: Expressões Algébricas | D25: Valor absoluto (módulo) | E25: Não Iniciado | F25: =LEFT(A25,2) -> Ma | G25: =A25&" - "&D25 -> Matemática - Valor absoluto (módulo)
A26: Matemática | B26: Nível 2 - Álgebra | C26: Funções | D26: Conceito de função | E26: Não Iniciado | F26: =LEFT(A26,2) -> Ma | G26: =A26&" - "&D26 -> Matemática - Conceito de função
A27: Matemática | B27: Nível 2 - Álgebra | C27: Funções | D27: Domínio e imagem | E27: Não Iniciado | F27: =LEFT(A27,2) -> Ma | G27: =A27&" - "&D27 -> Matemática - Domínio e imagem
A28: Matemática | B28: Nível 2 - Álgebra | C28: Funções | D28: Função afim | E28: Não Iniciado | F28: =LEFT(A28,2) -> Ma | G28: =A28&" - "&D28 -> Matemática - Função afim
A29: Matemática | B29: Nível 2 - Álgebra | C29: Funções | D29: Função quadrática | E29: Não Iniciado | F29: =LEFT(A29,2) -> Ma | G29: =A29&" - "&D29 -> Matemática - Função quadrática
A30: Matemática | B30: Nível 2 - Álgebra | C30: Funções | D30: Função modular | E30: Não Iniciado | F30: =LEFT(A30,2) -> Ma | G30: =A30&" - "&D30 -> Matemática - Função modular
... A66: Matemática | B66: Nível 3 - Geometria | C66: Geometria Analítica | D66: Perpendicularidade | E66: Não Iniciado | F66: =LEFT(A66,2) -> Ma | G66: =A66&" - "&D66 -> Matemática - Perpendicularidade
A67: Matemática | B67: Nível 4 - Estatística e Probabilidade | D67: Média | E67: Não Iniciado | F67: =LEFT(A67,2) -> Ma | G67: =A67&" - "&D67 -> Matemática - Média
A68: Matemática | B68: Nível 4 - Estatística e Probabilidade | D68: Moda | E68: Não Iniciado | F68: =LEFT(A68,2) -> Ma | G68: =A68&" - "&D68 -> Matemática - Moda
A69: Matemática | B69: Nível 4 - Estatística e Probabilidade | D69: Mediana | E69: Não Iniciado | F69: =LEFT(A69,2) -> Ma | G69: =A69&" - "&D69 -> Matemática - Mediana
A70: Matemática | B70: Nível 4 - Estatística e Probabilidade | D70: Desvio padrão | E70: Não Iniciado | F70: =LEFT(A70,2) -> Ma | G70: =A70&" - "&D70 -> Matemática - Desvio padrão
A71: Matemática | B71: Nível 4 - Estatística e Probabilidade | D71: Análise de gráficos | E71: Não Iniciado | F71: =LEFT(A71,2) -> Ma | G71: =A71&" - "&D71 -> Matemática - Análise de gráficos
A72: Matemática | B72: Nível 4 - Estatística e Probabilidade | D72: Tabelas | E72: Não Iniciado | F72: =LEFT(A72,2) -> Ma | G72: =A72&" - "&D72 -> Matemática - Tabelas
A73: Matemática | B73: Nível 4 - Estatística e Probabilidade | D73: Probabilidade simples | E73: Não Iniciado | F73: =LEFT(A73,2) -> Ma | G73: =A73&" - "&D73 -> Matemática - Probabilidade simples
A74: Matemática | B74: Nível 4 - Estatística e Probabilidade | D74: Probabilidade condicional | E74: Não Iniciado | F74: =LEFT(A74,2) -> Ma | G74: =A74&" - "&D74 -> Matemática - Probabilidade condicional
A75: Matemática | B75: Nível 4 - Estatística e Probabilidade | D75: Análise combinatória | E75: Não Iniciado | F75: =LEFT(A75,2) -> Ma | G75: =A75&" - "&D75 -> Matemática - Análise combinatória
A76: Matemática | B76: Nível 4 - Estatística e Probabilidade | D76: Permutações | E76: Não Iniciado | F76: =LEFT(A76,2) -> Ma | G76: =A76&" - "&D76 -> Matemática - Permutações
A77: Matemática | B77: Nível 4 - Estatística e Probabilidade | D77: Arranjos | E77: Não Iniciado | F77: =LEFT(A77,2) -> Ma | G77: =A77&" - "&D77 -> Matemática - Arranjos
A78: Matemática | B78: Nível 4 - Estatística e Probabilidade | D78: Combinações | E78: Não Iniciado | F78: =LEFT(A78,2) -> Ma | G78: =A78&" - "&D78 -> Matemática - Combinações
... A233: Português | B233: Literatura | D233: Literatura contemporânea | E233: Não Iniciado | F233: =LEFT(A233,2) -> Po | G233: =A233&" - "&D233 -> Português - Literatura contemporânea
...

Sheet Folha4
A1: =LEFT(C1,2) -> Ma | B1: 1 | C1: Matematica
A2: =LEFT(C2,2) -> Fí | B2: 2 | C2: Física
A3: =LEFT(C3,2) -> Qu | B3: 3 | C3: Química
A4: =LEFT(C4,2) -> Bi | B4: 4 | C4: Biologia
A5: =LEFT(C5,2) -> Po | B5: 5 | C5: Portugês
A6: =LEFT(C6,2) -> Re | B6: 6 | C6: Redação
A7: =LEFT(C7,2) -> Hi | B7: 7 | C7: História
A8: =LEFT(C8,2) -> Ge | B8: 8 | C8: Geografia
A9: =LEFT(C9,2) -> Fi | B9: 9 | C9: Filosofia
A10: =LEFT(C10,2) -> So | B10: 10 | C10: Sociologia
A11: =LEFT(C11,2) -> In | B11: 11 | C11: Ingles
A12: =LEFT(C12,2) -> Es | B12: 12 | C12: Espanhol
A13: =LEFT(C13,2) -> At | B13: 13 | C13: Atualidades

Sheet Calendário
A1: Data | B1: Conteúdo Novo | C1: Revisão 24h | D1: Revisão 7d | E1: Revisão 30d | F1: Revisão 90d | G1: Revisão 180d
A2: 46230 | B2: =IFERROR(INDEX(registro!$A:$A, MATCH($A2, registro!C:C, 0))," ") -> Português - Classes gramaticais | C2: =IFERROR(INDEX(registro!$A:$A, MATCH($A2, registro!D:D, 0))," ") | D2: =IFERROR(INDEX(registro!$A:$A, MATCH($A2, registro!E:E, 0))," ") | E2: =IFERROR(INDEX(registro!$A:$A, MATCH($A2, registro!F:F, 0))," ") | F2: =IFERROR(INDEX(registro!$A:$A, MATCH($A2, registro!G:G, 0))," ") | G2: =IFERROR(INDEX(registro!$A:$A, MATCH($A2, registro!H:H, 0))," ")
A3: 46231 | B3: =IFERROR(INDEX(registro!$A:$A, MATCH($A3, registro!C:C, 0))," ") | C3: =IFERROR(INDEX(registro!$A:$A, MATCH($A3, registro!D:D, 0))," ") -> Português - Classes gramaticais | D3: =IFERROR(INDEX(registro!$A:$A, MATCH($A3, registro!E:E, 0))," ") | E3: =IFERROR(INDEX(registro!$A:$A, MATCH($A3, registro!F:F, 0))," ") | F3: =IFERROR(INDEX(registro!$A:$A, MATCH($A3, registro!G:G, 0))," ") | G3: =IFERROR(INDEX(registro!$A:$A, MATCH($A3, registro!H:H, 0))," ")
A4: 46232 | B4: =IFERROR(INDEX(registro!$A:$A, MATCH($A4, registro!C:C, 0))," ") | C4: =IFERROR(INDEX(registro!$A:$A, MATCH($A4, registro!D:D, 0))," ") | D4: =IFERROR(INDEX(registro!$A:$A, MATCH($A4, registro!E:E, 0))," ") | E4: =IFERROR(INDEX(registro!$A:$A, MATCH($A4, registro!F:F, 0))," ") | F4: =IFERROR(INDEX(registro!$A:$A, MATCH($A4, registro!G:G, 0))," ") | G4: =IFERROR(INDEX(registro!$A:$A, MATCH($A4, registro!H:H, 0))," ")
A5: 46233 | B5: =IFERROR(INDEX(registro!$A:$A, MATCH($A5, registro!C:C, 0))," ") | C5: =IFERROR(INDEX(registro!$A:$A, MATCH($A5, registro!D:D, 0))," ") | D5: =IFERROR(INDEX(registro!$A:$A, MATCH($A5, registro!E:E, 0))," ") | E5: =IFERROR(INDEX(registro!$A:$A, MATCH($A5, registro!F:F, 0))," ") | F5: =IFERROR(INDEX(registro!$A:$A, MATCH($A5, registro!G:G, 0))," ") | G5: =IFERROR(INDEX(registro!$A:$A, MATCH($A5, registro!H:H, 0))," ")
A6: 46234 | B6: =IFERROR(INDEX(registro!$A:$A, MATCH($A6, registro!C:C, 0))," ") | C6: =IFERROR(INDEX(registro!$A:$A, MATCH($A6, registro!D:D, 0))," ") | D6: =IFERROR(INDEX(registro!$A:$A, MATCH($A6, registro!E:E, 0))," ") | E6: =IFERROR(INDEX(registro!$A:$A, MATCH($A6, registro!F:F, 0))," ") | F6: =IFERROR(INDEX(registro!$A:$A, MATCH($A6, registro!G:G, 0))," ") | G6: =IFERROR(INDEX(registro!$A:$A, MATCH($A6, registro!H:H, 0))," ")
A7: 46235 | B7: =IFERROR(INDEX(registro!$A:$A, MATCH($A7, registro!C:C, 0))," ") | C7: =IFERROR(INDEX(registro!$A:$A, MATCH($A7, registro!D:D, 0))," ") | D7: =IFERROR(INDEX(registro!$A:$A, MATCH($A7, registro!E:E, 0))," ") | E7: =IFERROR(INDEX(registro!$A:$A, MATCH($A7, registro!F:F, 0))," ") | F7: =IFERROR(INDEX(registro!$A:$A, MATCH($A7, registro!G:G, 0))," ") | G7: =IFERROR(INDEX(registro!$A:$A, MATCH($A7, registro!H:H, 0))," ")
A8: 46236 | B8: =IFERROR(INDEX(registro!$A:$A, MATCH($A8, registro!C:C, 0))," ") | C8: =IFERROR(INDEX(registro!$A:$A, MATCH($A8, registro!D:D, 0))," ") | D8: =IFERROR(INDEX(registro!$A:$A, MATCH($A8, registro!E:E, 0))," ") | E8: =IFERROR(INDEX(registro!$A:$A, MATCH($A8, registro!F:F, 0))," ") | F8: =IFERROR(INDEX(registro!$A:$A, MATCH($A8, registro!G:G, 0))," ") | G8: =IFERROR(INDEX(registro!$A:$A, MATCH($A8, registro!H:H, 0))," ")
A9: 46237 | B9: =IFERROR(INDEX(registro!$A:$A, MATCH($A9, registro!C:C, 0))," ") | C9: =IFERROR(INDEX(registro!$A:$A, MATCH($A9, registro!D:D, 0))," ") | D9: =IFERROR(INDEX(registro!$A:$A, MATCH($A9, registro!E:E, 0))," ") | E9: =IFERROR(INDEX(registro!$A:$A, MATCH($A9, registro!F:F, 0))," ") | F9: =IFERROR(INDEX(registro!$A:$A, MATCH($A9, registro!G:G, 0))," ") | G9: =IFERROR(INDEX(registro!$A:$A, MATCH($A9, registro!H:H, 0))," ")
A10: 46238 | B10: =IFERROR(INDEX(registro!$A:$A, MATCH($A10, registro!C:C, 0))," ") | C10: =IFERROR(INDEX(registro!$A:$A, MATCH($A10, registro!D:D, 0))," ") | D10: =IFERROR(INDEX(registro!$A:$A, MATCH($A10, registro!E:E, 0))," ") -> Português - Classes gramaticais | E10: =IFERROR(INDEX(registro!$A:$A, MATCH($A10, registro!F:F, 0))," ") | F10: =IFERROR(INDEX(registro!$A:$A, MATCH($A10, registro!G:G, 0))," ") | G10: =IFERROR(INDEX(registro!$A:$A, MATCH($A10, registro!H:H, 0))," ")
A11: 46239 | B11: =IFERROR(INDEX(registro!$A:$A, MATCH($A11, registro!C:C, 0))," ") | C11: =IFERROR(INDEX(registro!$A:$A, MATCH($A11, registro!D:D, 0))," ") | D11: =IFERROR(INDEX(registro!$A:$A, MATCH($A11, registro!E:E, 0))," ") | E11: =IFERROR(INDEX(registro!$A:$A, MATCH($A11, registro!F:F, 0))," ") | F11: =IFERROR(INDEX(registro!$A:$A, MATCH($A11, registro!G:G, 0))," ") | G11: =IFERROR(INDEX(registro!$A:$A, MATCH($A11, registro!H:H, 0))," ")
A12: 46240 | B12: =IFERROR(INDEX(registro!$A:$A, MATCH($A12, registro!C:C, 0))," ") | C12: =IFERROR(INDEX(registro!$A:$A, MATCH($A12, registro!D:D, 0))," ") | D12: =IFERROR(INDEX(registro!$A:$A, MATCH($A12, registro!E:E, 0))," ") | E12: =IFERROR(INDEX(registro!$A:$A, MATCH($A12, registro!F:F, 0))," ") | F12: =IFERROR(INDEX(registro!$A:$A, MATCH($A12, registro!G:G, 0))," ") | G12: =IFERROR(INDEX(registro!$A:$A, MATCH($A12, registro!H:H, 0))," ")
A13: 46241 | B13: =IFERROR(INDEX(registro!$A:$A, MATCH($A13, registro!C:C, 0))," ") | C13: =IFERROR(INDEX(registro!$A:$A, MATCH($A13, registro!D:D, 0))," ") | D13: =IFERROR(INDEX(registro!$A:$A, MATCH($A13, registro!E:E, 0))," ") | E13: =IFERROR(INDEX(registro!$A:$A, MATCH($A13, registro!F:F, 0))," ") | F13: =IFERROR(INDEX(registro!$A:$A, MATCH($A13, registro!G:G, 0))," ") | G13: =IFERROR(INDEX(registro!$A:$A, MATCH($A13, registro!H:H, 0))," ")
... A299: 46527 | B299: =IFERROR(INDEX(registro!$A:$A, MATCH($A299, registro!C:C, 0))," ") | C299: =IFERROR(INDEX(registro!$A:$A, MATCH($A299, registro!D:D, 0))," ") | D299: =IFERROR(INDEX(registro!$A:$A, MATCH($A299, registro!E:E, 0))," ") | E299: =IFERROR(INDEX(registro!$A:$A, MATCH($A299, registro!F:F, 0))," ") | F299: =IFERROR(INDEX(registro!$A:$A, MATCH($A299, registro!G:G, 0))," ") | G299: =IFERROR(INDEX(registro!$A:$A, MATCH($A299, registro!H:H, 0))," ")
A300: 46528
A301: 46529
A302: 46530
A303: 46531
A304: 46532

Sheet registro
A1: Materia | B1: Código | C1: Conteúdo Novo | D1: Revisão 24h | E1: Revisão 7d | F1: Revisão 30d | G1: Revisão 90d | H1: Revisão 180d
A2: Português - Classes gramaticais | B2: =VLOOKUP(LEFT(A2,2),Folha4!$A$1:$C$13,2,0) -> 5 | C2: 46230 | D2: =C2+1 -> 46231 | E2: =D2+7 -> 46238 | F2: =E2+30 -> 46268 | G2: =F2+90 -> 46358 | H2: =G2+180 -> 46538
B3: =VLOOKUP(LEFT(A3,2),Folha4!$A$1:$C$13,2,0) -> #N/A | D3: =C3+1 -> 1 | E3: =D3+7 -> 8 | F3: =E3+30 -> 38 | G3: =F3+90 -> 128 | H3: =G3+180 -> 308
B4: =VLOOKUP(LEFT(A4,2),Folha4!$A$1:$C$13,2,0) -> #N/A | D4: =C4+1 -> 1 | E4: =D4+7 -> 8 | F4: =E4+30 -> 38 | G4: =F4+90 -> 128 | H4: =G4+180 -> 308
B5: =VLOOKUP(LEFT(A5,2),Folha4!$A$1:$C$13,2,0) -> #N/A | D5: =C5+1 -> 1 | E5: =D5+7 -> 8 | F5: =E5+30 -> 38 | G5: =F5+90 -> 128 | H5: =G5+180 -> 308
B6: =VLOOKUP(LEFT(A6,2),Folha4!$A$1:$C$13,2,0) -> #N/A | D6: =C6+1 -> 1 | E6: =D6+7 -> 8 | F6: =E6+30 -> 38 | G6: =F6+90 -> 128 | H6: =G6+180 -> 308
B7: =VLOOKUP(LEFT(A7,2),Folha4!$A$1:$C$13,2,0) -> #N/A | D7: =C7+1 -> 1 | E7: =D7+7 -> 8 | F7: =E7+30 -> 38 | G7: =F7+90 -> 128 | H7: =G7+180 -> 308
B8: =VLOOKUP(LEFT(A8,2),Folha4!$A$1:$C$13,2,0) -> #N/A | D8: =C8+1 -> 1 | E8: =D8+7 -> 8 | F8: =E8+30 -> 38 | G8: =F8+90 -> 128 | H8: =G8+180 -> 308
B9: =VLOOKUP(LEFT(A9,2),Folha4!$A$1:$C$13,2,0) -> #N/A | D9: =C9+1 -> 1 | E9: =D9+7 -> 8 | F9: =E9+30 -> 38 | G9: =F9+90 -> 128 | H9: =G9+180 -> 308
B10: =VLOOKUP(LEFT(A10,2),Folha4!$A$1:$C$13,2,0) -> #N/A | D10: =C10+1 -> 1 | E10: =D10+7 -> 8 | F10: =E10+30 -> 38 | G10: =F10+90 -> 128 | H10: =G10+180 -> 308
B11: =VLOOKUP(LEFT(A11,2),Folha4!$A$1:$C$13,2,0) -> #N/A | D11: =C11+1 -> 1 | E11: =D11+7 -> 8 | F11: =E11+30 -> 38 | G11: =F11+90 -> 128 | H11: =G11+180 -> 308
B12: =VLOOKUP(LEFT(A12,2),Folha4!$A$1:$C$13,2,0) -> #N/A | D12: =C12+1 -> 1 | E12: =D12+7 -> 8 | F12: =E12+30 -> 38 | G12: =F12+90 -> 128 | H12: =G12+180 -> 308
B13: =VLOOKUP(LEFT(A13,2),Folha4!$A$1:$C$13,2,0) -> #N/A | D13: =C13+1 -> 1 | E13: =D13+7 -> 8 | F13: =E13+30 -> 38 | G13: =F13+90 -> 128 | H13: =G13+180 -> 308
B14: =VLOOKUP(LEFT(A14,2),Folha4!$A$1:$C$13,2,0) -> #N/A | D14: =C14+1 -> 1 | E14: =D14+7 -> 8 | F14: =E14+30 -> 38 | G14: =F14+90 -> 128 | H14: =G14+180 -> 308
... B33: =VLOOKUP(LEFT(A33,2),Folha4!$A$1:$C$13,2,0) -> #N/A | D33: =C33+1 -> 1 | E33: =D33+7 -> 8 | F33: =E33+30 -> 38 | G33: =F33+90 -> 128 | H33: =G33+180 -> 308
